Workbook

Sheet brands
A1: brand_id | B1: brand_name
A2: 1 | B2: Electra
A3: 2 | B3: Haro
A4: 3 | B4: Heller
A5: 4 | B5: Pure Cycles
A6: 5 | B6: Ritchey
A7: 6 | B7: Strider
A8: 7 | B8: Sun Bicycles
A9: 8 | B9: Surly
A10: 9 | B10: Trek

Sheet order_items 
A1: order_id | B1: item_id | C1: product_id | D1: quantity | E1: list_price | F1: discount | G1: Total price | H1: product_name
A2: 1 | B2: 1 | C2: 20 | D2: 1 | E2: 599.99 | F2: 0.2 | G2: =E2*D2-F2 -> 599.79 | H2: =VLOOKUP(C2,'products '!$A$1:$G$322,2,FALSE) -> Electra Townie Original 7D EQ - Women's - 2016
A3: 2 | B3: 1 | C3: 20 | D3: 1 | E3: 599.99 | F3: 0.07 | G3: =E3*D3-F3 -> 599.92 | H3: =VLOOKUP(C3,'products '!$A$1:$G$322,2,FALSE) -> Electra Townie Original 7D EQ - Women's - 2016
A4: 3 | B4: 1 | C4: 3 | D4: 1 | E4: 999.99 | F4: 0.05 | G4: =E4*D4-F4 -> 999.94 | H4: =VLOOKUP(C4,'products '!$A$1:$G$322,2,FALSE) -> Surly Wednesday Frameset - 2016
A5: 4 | B5: 1 | C5: 2 | D5: 2 | E5: 749.99 | F5: 0.1 | G5: =E5*D5-F5 -> 1499.88 | H5: =VLOOKUP(C5,'products '!$A$1:$G$322,2,FALSE) -> Ritchey Timberwolf Frameset - 2016
A6: 5 | B6: 1 | C6: 10 | D6: 2 | E6: 1549 | F6: 0.05 | G6: =E6*D6-F6 -> 3097.95 | H6: =VLOOKUP(C6,'products '!$A$1:$G$322,2,FALSE) -> Surly Straggler - 2016
A7: 6 | B7: 1 | C7: 18 | D7: 1 | E7: 449 | F7: 0.07 | G7: =E7*D7-F7 -> 448.93 | H7: =VLOOKUP(C7,'products '!$A$1:$G$322,2,FALSE) -> Pure Cycles Western 3-Speed - Women's - 2015/2016
A8: 7 | B8: 1 | C8: 15 | D8: 1 | E8: 529.99 | F8: 0.07 | G8: =E8*D8-F8 -> 529.92 | H8: =VLOOKUP(C8,'products '!$A$1:$G$322,2,FALSE) -> Electra Moto 1 - 2016
A9: 8 | B9: 1 | C9: 22 | D9: 1 | E9: 269.99 | F9: 0.05 | G9: =E9*D9-F9 -> 269.94 | H9: =VLOOKUP(C9,'products '!$A$1:$G$322,2,FALSE) -> Electra Girl's Hawaii 1 (16-inch) - 2015/2016
A10: 9 | B10: 1 | C10: 7 | D10: 2 | E10: 3999.99 | F10: 0.1 | G10: =E10*D10-F10 -> 7999.88 | H10: =VLOOKUP(C10,'products '!$A$1:$G$322,2,FALSE) -> Trek Slash 8 27.5 - 2016
A11: 10 | B11: 1 | C11: 14 | D11: 1 | E11: 269.99 | F11: 0.1 | G11: =E11*D11-F11 -> 269.89 | H11: =VLOOKUP(C11,'products '!$A$1:$G$322,2,FALSE) -> Electra Girl's Hawaii 1 (16-inch) - 2015/2016
A12: 11 | B12: 1 | C12: 8 | D12: 1 | E12: 1799.99 | F12: 0.05 | G12: =E12*D12-F12 -> 1799.94 | H12: =VLOOKUP(C12,'products '!$A$1:$G$322,2,FALSE) -> Trek Remedy 29 Carbon Frameset - 2016
A13: 12 | B13: 1 | C13: 4 | D13: 2 | E13: 2899.99 | F13: 0.1 | G13: =E13*D13-F13 -> 5799.88 | H13: =VLOOKUP(C13,'products '!$A$1:$G$322,2,FALSE) -> Trek Fuel EX 8 29 - 2016
... A1616: 1615 | B1616: 1 | C1616: 197 | D1616: 2 | E1616: 2299.99 | F1616: 0.2 | G1616: =E1616*D1616-F1616 -> 4599.78 | H1616: =VLOOKUP(C1616,'products '!$A$1:$G$322,2,FALSE) -> Trek Verve+ Lowstep - 2018

Sheet stocks
A1: store_id | B1: product_id | C1: quantity
A2: 1 | B2: 1 | C2: 27
A3: 1 | B3: 2 | C3: 5
A4: 1 | B4: 3 | C4: 6
A5: 1 | B5: 4 | C5: 23
A6: 1 | B6: 5 | C6: 22
A7: 1 | B7: 6 | C7: 0
A8: 1 | B8: 7 | C8: 8
A9: 1 | B9: 8 | C9: 0
A10: 1 | B10: 9 | C10: 11
A11: 1 | B11: 10 | C11: 15
A12: 1 | B12: 11 | C12: 8
A13: 1 | B13: 12 | C13: 16
... A940: 3 | B940: 313 | C940: 0

Sheet PIVOT
A3: Row Labels | B3: Sum of list_price
A4: Children Bicycles | B4: 16979.41
A5: Comfort Bicycles | B5: 20463.7
A6: Cruisers Bicycles | B6: 56972.16
A7: Cyclocross Bicycles | B7: 25427.93
A8: Electric Bikes | B8: 78759.76
A9: Mountain Bikes | B9: 98985.44
A10: Road Bikes | B10: 190521.44
A11: Grand Total | B11: 488109.84

Sheet products 
A1: product_id | B1: product_name | C1: brand_id | D1: category_id | E1: model_year | F1: list_price | G1: category_name
A2: 155 | B2: Trek Domane SLR 9 Disc - 2018 | C2: 9 | D2: 7 | E2: 2018 | F2: 11999.99 | G2: =VLOOKUP(D2,categories!$A$1:$B$8,2,FALSE) -> Road Bikes
A3: 149 | B3: Trek Domane SLR 8 Disc - 2018 | C3: 9 | D3: 7 | E3: 2018 | F3: 7499.99 | G3: =VLOOKUP(D3,categories!$A$1:$B$8,2,FALSE) -> Road Bikes
A4: 51 | B4: Trek Silque SLR 8 Women's - 2017 | C4: 9 | D4: 7 | E4: 2017 | F4: 6499.99 | G4: =VLOOKUP(D4,categories!$A$1:$B$8,2,FALSE) -> Road Bikes
A5: 156 | B5: Trek Domane SL Frameset - 2018 | C5: 9 | D5: 7 | E5: 2018 | F5: 6499.99 | G5: =VLOOKUP(D5,categories!$A$1:$B$8,2,FALSE) -> Road Bikes
A6: 157 | B6: Trek Domane SL Frameset Women's - 2018 | C6: 9 | D6: 7 | E6: 2018 | F6: 6499.99 | G6: =VLOOKUP(D6,categories!$A$1:$B$8,2,FALSE) -> Road Bikes
A7: 169 | B7: Trek Emonda SLR 8 - 2018 | C7: 9 | D7: 7 | E7: 2018 | F7: 6499.99 | G7: =VLOOKUP(D7,categories!$A$1:$B$8,2,FALSE) -> Road Bikes
A8: 50 | B8: Trek Silque SLR 7 Women's - 2017 | C8: 9 | D8: 7 | E8: 2017 | F8: 5999.99 | G8: =VLOOKUP(D8,categories!$A$1:$B$8,2,FALSE) -> Road Bikes
A9: 56 | B9: Trek Domane SLR 6 Disc - 2017 | C9: 9 | D9: 7 | E9: 2017 | F9: 5499.99 | G9: =VLOOKUP(D9,categories!$A$1:$B$8,2,FALSE) -> Road Bikes
A10: 148 | B10: Trek Domane SL 8 Disc - 2018 | C10: 9 | D10: 7 | E10: 2018 | F10: 5499.99 | G10: =VLOOKUP(D10,categories!$A$1:$B$8,2,FALSE) -> Road Bikes
A11: 154 | B11: Trek Domane SLR 6 Disc Women's - 2018 | C11: 9 | D11: 7 | E11: 2018 | F11: 5499.99 | G11: =VLOOKUP(D11,categories!$A$1:$B$8,2,FALSE) -> Road Bikes
A12: 177 | B12: Trek Domane SLR 6 Disc - 2018 | C12: 9 | D12: 7 | E12: 2018 | F12: 5499.99 | G12: =VLOOKUP(D12,categories!$A$1:$B$8,2,FALSE) -> Road Bikes
A13: 43 | B13: Trek Fuel EX 9.8 27.5 Plus - 2017 | C13: 9 | D13: 6 | E13: 2017 | F13: 5299.99 | G13: =VLOOKUP(D13,categories!$A$1:$B$8,2,FALSE) -> Mountain Bikes
... A322: 263 | B322: Strider Classic 12 Balance Bike - 2018 | C322: 6 | D322: 1 | E322: 2018 | F322: 89.99 | G322: =VLOOKUP(D322,categories!$A$1:$B$8,2,FALSE) -> Children Bicycles

Sheet stores 
A1: store_id | B1: store_name | C1: phone | D1: email | E1: street | F1: city | G1: state | H1: zip_code
A2: 1 | B2: Santa Cruz Bikes | C2: (831) 476-4321 | D2: santacruz@bikes.shop | E2: 3700 Portola Drive | F2: Santa Cruz | G2: CA | H2: 95060
A3: 2 | B3: Baldwin Bikes | C3: (516) 379-8888 | D3: baldwin@bikes.shop | E3: 4200 Chestnut Lane | F3: Baldwin | G3: NY | H3: 11432
A4: 3 | B4: Rowlett Bikes | C4: (972) 530-5555 | D4: rowlett@bikes.shop | E4: 8000 Fairway Avenue | F4: Rowlett | G4: TX | H4: 75088

Sheet staffs 
A1: staff_id | B1: first_name | C1: last_name | D1: email | E1: phone | F1: active | G1: store_id | H1: manager_id
A2: 1 | B2: Fabiola | C2: Jackson | D2: fabiola.jackson@bikes.shop | E2: (831) 555-5554 | F2: 1 | G2: 1 | H2: NA
A3: 2 | B3: Mireya | C3: Copeland | D3: mireya.copeland@bikes.shop | E3: (831) 555-5555 | F3: 1 | G3: 1 | H3: 1
A4: 3 | B4: Genna | C4: Serrano | D4: genna.serrano@bikes.shop | E4: (831) 555-5556 | F4: 1 | G4: 1 | H4: 2
A5: 4 | B5: Virgie | C5: Wiggins | D5: virgie.wiggins@bikes.shop | E5: (831) 555-5557 | F5: 1 | G5: 1 | H5: 2
A6: 5 | B6: Jannette | C6: David | D6: jannette.david@bikes.shop | E6: (516) 379-4444 | F6: 1 | G6: 2 | H6: 1
A7: 6 | B7: Marcelene | C7: Boyer | D7: marcelene.boyer@bikes.shop | E7: (516) 379-4445 | F7: 1 | G7: 2 | H7: 5
A8: 7 | B8: Venita | C8: Daniel | D8: venita.daniel@bikes.shop | E8: (516) 379-4446 | F8: 1 | G8: 2 | H8: 5
A9: 8 | B9: Kali | C9: Vargas | D9: kali.vargas@bikes.shop | E9: (972) 530-5555 | F9: 1 | G9: 3 | H9: 1
A10: 9 | B10: Layla | C10: Terrell | D10: layla.terrell@bikes.shop | E10: (972) 530-5556 | F10: 1 | G10: 3 | H10: 7
A11: 10 | B11: Bernardine | C11: Houston | D11: bernardine.houston@bikes.shop | E11: (972) 530-5557 | F11: 1 | G11: 3 | H11: 7

Sheet customers 
A1: customer_id | B1: first_name | C1: last_name | D1: phone | E1: email | F1: street | G1: city | H1: state | I1: zip_code
A2: 1 | B2: Debra | C2: Burks | D2: NA | E2: debra.burks@yahoo.com | F2: 9273 Thorne Ave. | G2: Orchard Park | H2: NY | I2: 14127
A3: 2 | B3: Kasha | C3: Todd | D3: NA | E3: kasha.todd@yahoo.com | F3: 910 Vine Street | G3: Campbell | H3: CA | I3: 95008
A4: 3 | B4: Tameka | C4: Fisher | D4: NA | E4: tameka.fisher@aol.com | F4: 769C Honey Creek St. | G4: Redondo Beach | H4: CA | I4: 90278
A5: 4 | B5: Daryl | C5: Spence | D5: NA | E5: daryl.spence@aol.com | F5: 988 Pearl Lane | G5: Uniondale | H5: NY | I5: 11553
A6: 5 | B6: Charolette | C6: Rice | D6: (916) 381-6003 | E6: charolette.rice@msn.com | F6: 107 River Dr. | G6: Sacramento | H6: CA | I6: 95820
A7: 6 | B7: Lyndsey | C7: Bean | D7: NA | E7: lyndsey.bean@hotmail.com | F7: 769 West Road | G7: Fairport | H7: NY | I7: 14450
A8: 7 | B8: Latasha | C8: Hays | D8: (716) 986-3359 | E8: latasha.hays@hotmail.com | F8: 7014 Manor Station Rd. | G8: Buffalo | H8: NY | I8: 14215
A9: 8 | B9: Jacquline | C9: Duncan | D9: NA | E9: jacquline.duncan@yahoo.com | F9: 15 Brown St. | G9: Jackson Heights | H9: NY | I9: 11372
A10: 9 | B10: Genoveva | C10: Baldwin | D10: NA | E10: genoveva.baldwin@msn.com | F10: 8550 Spruce Drive | G10: Port Washington | H10: NY | I10: 11050
A11: 10 | B11: Pamelia | C11: Newman | D11: NA | E11: pamelia.newman@gmail.com | F11: 476 Chestnut Ave. | G11: Monroe | H11: NY | I11: 10950
A12: 11 | B12: Deshawn | C12: Mendoza | D12: NA | E12: deshawn.mendoza@yahoo.com | F12: 8790 Cobblestone Street | G12: Monsey | H12: NY | I12: 10952
A13: 12 | B13: Robby | C13: Sykes | D13: (516) 583-7761 | E13: robby.sykes@hotmail.com | F13: 486 Rock Maple Street | G13: Hempstead | H13: NY | I13: 11550
... A1446: 1445 | B1446: Ester | C1446: Acevedo | D1446: NA | E1446: ester.acevedo@gmail.com | F1446: 671 Miles Court | G1446: San Lorenzo | H1446: CA | I1446: 94580

Sheet orders
A1: order_id | B1: customer_id | C1: order_status | D1: order_date | E1: required_date | F1: shipped_date | G1: store_id | H1: staff_id
A2: 1 | B2: 259 | C2: Delivered | D2: 42370 | E2: 42372 | F2: 2016-01-03 | G2: 1 | H2: 2
A3: 2 | B3: 1212 | C3: Delivered | D3: 42370 | E3: 42373 | F3: 2016-01-03 | G3: 2 | H3: 6
A4: 3 | B4: 523 | C4: Delivered | D4: 42371 | E4: 42374 | F4: 2016-01-03 | G4: 2 | H4: 7
A5: 4 | B5: 175 | C5: Delivered | D5: 42372 | E5: 42373 | F5: 2016-01-05 | G5: 1 | H5: 3
A6: 5 | B6: 1324 | C6: Delivered | D6: 42372 | E6: 42375 | F6: 2016-01-06 | G6: 2 | H6: 6
A7: 6 | B7: 94 | C7: Delivered | D7: 42373 | E7: 42376 | F7: 2016-01-05 | G7: 2 | H7: 6
A8: 7 | B8: 324 | C8: Delivered | D8: 42373 | E8: 42376 | F8: 2016-01-05 | G8: 2 | H8: 6
A9: 8 | B9: 1204 | C9: Delivered | D9: 42373 | E9: 42374 | F9: 2016-01-05 | G9: 2 | H9: 7
A10: 9 | B10: 60 | C10: Delivered | D10: 42374 | E10: 42377 | F10: 2016-01-08 | G10: 1 | H10: 2
A11: 10 | B11: 442 | C11: Delivered | D11: 42374 | E11: 42375 | F11: 2016-01-06 | G11: 2 | H11: 6
A12: 11 | B12: 1326 | C12: Delivered | D12: 42374 | E12: 42377 | F12: 2016-01-07 | G12: 2 | H12: 7
A13: 12 | B13: 91 | C13: Delivered | D13: 42375 | E13: 42377 | F13: 2016-01-09 | G13: 1 | H13: 2
... A70: 69 | B70: 1413 | C70: Delivered | D70: 42410 | E70: 42412 | F70: 2016-02-11 | G70: 2 | H70: 7
A71: 70 | B71: 50 | C71: Shipped | D71: 42411 | E71: 42411 | F71: =orders___orders[[#This Row],[order_date]]+3 -> 42414 | G71: 3 | H71: 9
A72: 71 | B72: 797 | C72: Delivered | D72: 42411 | E72: 42414 | F72: 2016-02-12 | G72: 2 | H72: 7
A73: 72 | B73: 1386 | C73: Delivered | D73: 42412 | E73: 42415 | F73: 2016-02-13 | G73: 1 | H73: 2
A74: 73 | B74: 612 | C74: Delivered | D74: 42412 | E74: 42415 | F74: 2016-02-14 | G74: 2 | H74: 7
A75: 74 | B75: 264 | C75: Delivered | D75: 42413 | E75: 42415 | F75: 2016-02-15 | G75: 2 | H75: 7
A76: 75 | B76: 587 | C76: Delivered | D76: 42414 | E76: 42415 | F76: 2016-02-17 | G76: 2 | H76: 6
A77: 76 | B77: 9 | C77: Shipped | D77: 42416 | E77: 42416 | F77: =orders___orders[[#This Row],[order_date]]+3 -> 42419 | G77: 2 | H77: 6
A78: 77 | B78: 385 | C78: Delivered | D78: 42416 | E78: 42419 | F78: 2016-02-19 | G78: 1 | H78: 2
A79: 78 | B79: 1182 | C79: Delivered | D79: 42416 | E79: 42418 | F79: 2016-02-19 | G79: 2 | H79: 7
A80: 79 | B80: 529 | C80: Delivered | D80: 42417 | E80: 42420 | F80: 2016-02-20 | G80: 1 | H80: 3
A81: 80 | B81: 397 | C81: Delivered | D81: 42417 | E81: 42420 | F81: 2016-02-19 | G81: 2 | H81: 6
A82: 81 | B82: 521 | C82: Delivered | D82: 42417 | E82: 42419 | F82: 2016-02-18 | G82: 2 | H82: 6
A83: 82 | B83: 1223 | C83: Delivered | D83: 42418 | E83: 42421 | F83: 2016-02-20 | G83: 2 | H83: 6
A84: 83 | B84: 393 | C84: Delivered | D84: 42419 | E84: 42420 | F84: 2016-02-20 | G84: 1 | H84: 3
A85: 84 | B85: 317 | C85: Delivered | D85: 42420 | E85: 42422 | F85: 2016-02-21 | G85: 2 | H85: 7
A86: 85 | B86: 1174 | C86: Delivered | D86: 42420 | E86: 42423 | F86: 2016-02-21 | G86: 2 | H86: 7
A87: 86 | B87: 276 | C87: Delivered | D87: 42421 | E87: 42422 | F87: 2016-02-23 | G87: 2 | H87: 7
A88: 87 | B88: 516 | C88: Delivered | D88: 42421 | E88: 42422 | F88: 2016-02-23 | G88: 2 | H88: 6
A89: 88 | B89: 1069 | C89: Delivered | D89: 42421 | E89: 42422 | F89: 2016-02-23 | G89: 2 | H89: 6
... A158: 157 | B158: 43 | C158: Delivered | D158: 42463 | E158: 42466 | F158: 2016-04-06 | G158: 3 | H158: 8
A159: 158 | B159: 117 | C159: Shipped | D159: 42464 | E159: 42464 | F159: =orders___orders[[#This Row],[order_date]]+3 -> 42467 | G159: 3 | H159: 9
A160: 159 | B160: 32 | C160: Delivered | D160: 42464 | E160: 42466 | F160: 2016-04-06 | G160: 1 | H160: 2
A161: 160 | B161: 205 | C161: Delivered | D161: 42464 | E161: 42466 | F161: 2016-04-06 | G161: 2 | H161: 7
A162: 161 | B162: 251 | C162: Delivered | D162: 42464 | E162: 42467 | F162: 2016-04-05 | G162: 2 | H162: 7
A163: 162 | B163: 31 | C163: Delivered | D163: 42466 | E163: 42468 | F163: 2016-04-07 | G163: 1 | H163: 3
A164: 163 | B164: 1325 | C164: Delivered | D164: 42466 | E164: 42467 | F164: 2016-04-07 | G164: 2 | H164: 7
...

Sheet categories
A1: category_id | B1: category_name
A2: 1 | B2: Children Bicycles
A3: 2 | B3: Comfort Bicycles
A4: 3 | B4: Cruisers Bicycles
A5: 4 | B5: Cyclocross Bicycles
A6: 5 | B6: Electric Bikes
A7: 6 | B7: Mountain Bikes
A8: 7 | B8: Road Bikes
